Parallel: 3. Serial: 0
test_issue_5087 (numba.tests.test_byteflow.TestByteFlowIssues.test_issue_5087) ... ERROR
test_issue_5097 (numba.tests.test_byteflow.TestByteFlowIssues.test_issue_5097) ... ok
test_issue_5680 (numba.tests.test_byteflow.TestByteFlowIssues.test_issue_5680) ... ok

======================================================================
ERROR: test_issue_5087 (numba.tests.test_byteflow.TestByteFlowIssues.test_issue_5087)
----------------------------------------------------------------------
Traceback (most recent call last):
  File "/mnt/home/sklam/dev/numba-py312-workspace/numba/numba/tests/test_byteflow.py", line 69, in test_issue_5087
    run_frontend(udt)
  File "/mnt/home/sklam/dev/numba-py312-workspace/numba/numba/core/compiler.py", line 334, in run_frontend
    func_ir = interp.interpret(bc)
              ^^^^^^^^^^^^^^^^^^^^
  File "/mnt/home/sklam/dev/numba-py312-workspace/numba/numba/core/interpreter.py", line 1363, in interpret
    flow.run()
  File "/mnt/home/sklam/dev/numba-py312-workspace/numba/numba/core/byteflow.py", line 114, in run
    runner.dispatch(state)
  File "/mnt/home/sklam/dev/numba-py312-workspace/numba/numba/core/byteflow.py", line 344, in dispatch
    raise UnsupportedError(msg, loc=self.get_debug_loc(inst.lineno))
numba.core.errors.UnsupportedError: Use of unsupported opcode (EXTENDED_ARG) found

File "numba/tests/test_byteflow.py", line 22:
        def udt():
            <source elided>

            for i in range:
            ^


----------------------------------------------------------------------
Ran 3 tests in 0.153s

FAILED (errors=1)
