Parallel: 16. Serial: 0
test_c01 (numba.tests.test_lists.TestListOfList.test_c01) ... ok
test_c02 (numba.tests.test_lists.TestListOfList.test_c02) ... ok
test_c03 (numba.tests.test_lists.TestListOfList.test_c03) ... ok
test_c04 (numba.tests.test_lists.TestListOfList.test_c04) ... ok
test_c05 (numba.tests.test_lists.TestListOfList.test_c05) ... ok
test_c06 (numba.tests.test_lists.TestListOfList.test_c06) ... ok
test_c07 (numba.tests.test_lists.TestListOfList.test_c07) ... ok
test_c08 (numba.tests.test_lists.TestListOfList.test_c08) ... ok
test_c09 (numba.tests.test_lists.TestListOfList.test_c09) ... ok
test_c10 (numba.tests.test_lists.TestListOfList.test_c10) ... ok
test_c11 (numba.tests.test_lists.TestListOfList.test_c11) ... ok
test_c12 (numba.tests.test_lists.TestListOfList.test_c12) ... ok
test_heterogeneous_list (numba.tests.test_lists.TestListOfList.test_heterogeneous_list) ... ok
test_heterogeneous_list_error (numba.tests.test_lists.TestListOfList.test_heterogeneous_list_error) ... ok
test_list_of_list_reflected (numba.tests.test_lists.TestListOfList.test_list_of_list_reflected) ... ok
test_returning_list_of_list (numba.tests.test_lists.TestListOfList.test_returning_list_of_list) ... ERROR

======================================================================
ERROR: test_returning_list_of_list (numba.tests.test_lists.TestListOfList.test_returning_list_of_list)
----------------------------------------------------------------------
Traceback (most recent call last):
  File "/mnt/home/sklam/dev/numba-py312-workspace/numba/numba/core/ir.py", line 271, in get
    return self._con[name]
           ~~~~~~~~~^^^^^^
KeyError: 'i'

During handling of the above exception, another exception occurred:

Traceback (most recent call last):
  File "/mnt/home/sklam/dev/numba-py312-workspace/numba/numba/core/ir.py", line 1178, in get_exact
    return self.localvars.get(name)
           ^^^^^^^^^^^^^^^^^^^^^^^^
  File "/mnt/home/sklam/dev/numba-py312-workspace/numba/numba/core/ir.py", line 273, in get
    raise NotDefinedError(name)
numba.core.errors.NotDefinedError: The compiler failed to analyze the bytecode. Variable 'i' is not defined.

During handling of the above exception, another exception occurred:

Traceback (most recent call last):
  File "/mnt/home/sklam/dev/numba-py312-workspace/numba/numba/core/ir.py", line 271, in get
    return self._con[name]
           ~~~~~~~~~^^^^^^
KeyError: 'i'

During handling of the above exception, another exception occurred:

Traceback (most recent call last):
  File "/mnt/home/sklam/dev/numba-py312-workspace/numba/numba/core/interpreter.py", line 1783, in _dispatch
    return fn(inst, **kws)
           ^^^^^^^^^^^^^^^
  File "/mnt/home/sklam/dev/numba-py312-workspace/numba/numba/core/interpreter.py", line 2148, in op_LOAD_FAST
    self.store(value=self.get(srcname), name=res)
                     ^^^^^^^^^^^^^^^^^
  File "/mnt/home/sklam/dev/numba-py312-workspace/numba/numba/core/interpreter.py", line 1829, in get
    var = self.current_scope.get(name)
          ^^^^^^^^^^^^^^^^^^^^^^^^^^^^
  File "/mnt/home/sklam/dev/numba-py312-workspace/numba/numba/core/ir.py", line 1170, in get
    return self.get_exact(name)
           ^^^^^^^^^^^^^^^^^^^^
  File "/mnt/home/sklam/dev/numba-py312-workspace/numba/numba/core/ir.py", line 1181, in get_exact
    return self.parent.get(name)
           ^^^^^^^^^^^^^^^^^^^^^
  File "/mnt/home/sklam/dev/numba-py312-workspace/numba/numba/core/ir.py", line 1170, in get
    return self.get_exact(name)
           ^^^^^^^^^^^^^^^^^^^^
  File "/mnt/home/sklam/dev/numba-py312-workspace/numba/numba/core/ir.py", line 1178, in get_exact
    return self.localvars.get(name)
           ^^^^^^^^^^^^^^^^^^^^^^^^
  File "/mnt/home/sklam/dev/numba-py312-workspace/numba/numba/core/ir.py", line 273, in get
    raise NotDefinedError(name)
numba.core.errors.NotDefinedError: The compiler failed to analyze the bytecode. Variable 'i' is not defined.

During handling of the above exception, another exception occurred:

Traceback (most recent call last):
  File "/mnt/home/sklam/dev/numba-py312-workspace/numba/numba/tests/test_lists.py", line 1132, in test_returning_list_of_list
    self.compile_and_test(pyfunc)
  File "/mnt/home/sklam/dev/numba-py312-workspace/numba/numba/tests/test_lists.py", line 1117, in compile_and_test
    got = cfunc(*njit_args)
          ^^^^^^^^^^^^^^^^^
  File "/mnt/home/sklam/dev/numba-py312-workspace/numba/numba/core/dispatcher.py", line 476, in _compile_for_args
    error_rewrite(e, 'interpreter')
  File "/mnt/home/sklam/dev/numba-py312-workspace/numba/numba/core/dispatcher.py", line 407, in error_rewrite
    raise e
  File "/mnt/home/sklam/dev/numba-py312-workspace/numba/numba/core/dispatcher.py", line 420, in _compile_for_args
    return_val = self.compile(tuple(argtypes))
                 ^^^^^^^^^^^^^^^^^^^^^^^^^^^^^
  File "/mnt/home/sklam/dev/numba-py312-workspace/numba/numba/core/dispatcher.py", line 965, in compile
    cres = self._compiler.compile(args, return_type)
           ^^^^^^^^^^^^^^^^^^^^^^^^^^^^^^^^^^^^^^^^^
  File "/mnt/home/sklam/dev/numba-py312-workspace/numba/numba/core/dispatcher.py", line 125, in compile
    status, retval = self._compile_cached(args, return_type)
                     ^^^^^^^^^^^^^^^^^^^^^^^^^^^^^^^^^^^^^^^
  File "/mnt/home/sklam/dev/numba-py312-workspace/numba/numba/core/dispatcher.py", line 139, in _compile_cached
    retval = self._compile_core(args, return_type)
             ^^^^^^^^^^^^^^^^^^^^^^^^^^^^^^^^^^^^^
  File "/mnt/home/sklam/dev/numba-py312-workspace/numba/numba/core/dispatcher.py", line 152, in _compile_core
    cres = compiler.compile_extra(self.targetdescr.typing_context,
           ^^^^^^^^^^^^^^^^^^^^^^^^^^^^^^^^^^^^^^^^^^^^^^^^^^^^^^^
  File "/mnt/home/sklam/dev/numba-py312-workspace/numba/numba/core/compiler.py", line 770, in compile_extra
    return pipeline.compile_extra(func)
           ^^^^^^^^^^^^^^^^^^^^^^^^^^^^
  File "/mnt/home/sklam/dev/numba-py312-workspace/numba/numba/core/compiler.py", line 461, in compile_extra
    return self._compile_bytecode()
           ^^^^^^^^^^^^^^^^^^^^^^^^
  File "/mnt/home/sklam/dev/numba-py312-workspace/numba/numba/core/compiler.py", line 529, in _compile_bytecode
    return self._compile_core()
           ^^^^^^^^^^^^^^^^^^^^
  File "/mnt/home/sklam/dev/numba-py312-workspace/numba/numba/core/compiler.py", line 508, in _compile_core
    raise e
  File "/mnt/home/sklam/dev/numba-py312-workspace/numba/numba/core/compiler.py", line 495, in _compile_core
    pm.run(self.state)
  File "/mnt/home/sklam/dev/numba-py312-workspace/numba/numba/core/compiler_machinery.py", line 368, in run
    raise patched_exception
  File "/mnt/home/sklam/dev/numba-py312-workspace/numba/numba/core/compiler_machinery.py", line 356, in run
    self._runPass(idx, pass_inst, state)
  File "/mnt/home/sklam/dev/numba-py312-workspace/numba/numba/core/compiler_lock.py", line 35, in _acquire_compile_lock
    return func(*args, **kwargs)
           ^^^^^^^^^^^^^^^^^^^^^
  File "/mnt/home/sklam/dev/numba-py312-workspace/numba/numba/core/compiler_machinery.py", line 311, in _runPass
    mutated |= check(pss.run_pass, internal_state)
               ^^^^^^^^^^^^^^^^^^^^^^^^^^^^^^^^^^^
  File "/mnt/home/sklam/dev/numba-py312-workspace/numba/numba/core/compiler_machinery.py", line 273, in check
    mangled = func(compiler_state)
              ^^^^^^^^^^^^^^^^^^^^
  File "/mnt/home/sklam/dev/numba-py312-workspace/numba/numba/core/untyped_passes.py", line 86, in run_pass
    func_ir = interp.interpret(bc)
              ^^^^^^^^^^^^^^^^^^^^
  File "/mnt/home/sklam/dev/numba-py312-workspace/numba/numba/core/interpreter.py", line 1379, in interpret
    self._dispatch(inst, kws)
  File "/mnt/home/sklam/dev/numba-py312-workspace/numba/numba/core/interpreter.py", line 1794, in _dispatch
    raise err
numba.core.errors.NotDefinedError: Failed in nopython mode pipeline (step: analyzing bytecode)
The compiler failed to analyze the bytecode. Variable 'i' is not defined.

File "numba/tests/test_lists.py", line 1129:
        def pyfunc():
            a = [[np.arange(i)] for i in range(4)]
            ^


----------------------------------------------------------------------
Ran 16 tests in 4.386s

FAILED (errors=1)
